<?xml version="1.0"?>
<robot name="small_ros">

  <!-- Base Link -->
  <link name="base_link">
    <inertial>
      <origin xyz="0 0 0" rpy="0 0 0"/>
      <mass value="5.0"/>
      <inertia ixx="0.083" ixy="0.0" ixz="0.0"
               iyy="0.083" iyz="0.0" izz="0.083"/>
    </inertial>
    <visual>
      <origin xyz="0 0 0" rpy="0 0 0"/>
      <geometry>
        <mesh filename="/home/athira/Documents/Small_ROS/src/meshes/base_link.STL"/>
      </geometry>
      <material name="blue">
        <color rgba="0.792 0.820 0.933 1"/>
      </material>
    </visual>
    <collision>
      <origin xyz="0 0 0" rpy="0 0 0"/>
      <geometry>
        <mesh filename="/home/athira/Documents/Small_ROS/src/meshes/base_link.STL"/>
      </geometry>
    </collision>
  </link>

  <!-- Left Front Wheel -->
  <link name="Left_FR_Wheel">
    <inertial>
      <origin xyz="0 0 0" rpy="0 0 0"/>
      <mass value="0.5"/>
      <inertia ixx="0.004" ixy="0.0" ixz="0.0"
               iyy="0.004" iyz="0.0" izz="0.002"/>
    </inertial>
    <visual>
      <origin xyz="0 0 0" rpy="0 0 0"/>
      <geometry>
        <mesh filename="/home/athira/Documents/Small_ROS/src/meshes/Left_FR_Wheel.STL"/>
      </geometry>
      <material name="blue">
        <color rgba="0.792 0.820 0.933 1"/>
      </material>
    </visual>
    <collision>
      <origin xyz="0 0 0" rpy="0 0 0"/>
      <geometry>
        <mesh filename="/home/athira/Documents/Small_ROS/src/meshes/Left_FR_Wheel.STL"/>
      </geometry>
    </collision>
  </link>
  
  <joint name="Left_FR_Wheel_joint" type="continuous">
    <parent link="base_link"/>
    <child link="Left_FR_Wheel"/>
    <origin xyz="0.2 0.15 -0.1" rpy="0 0 0"/>
    <axis xyz="0 1 0"/>
    <limit effort="5" velocity="3"/>
    <dynamics damping="0.5" friction="0.1"/>
  </joint>

  <!-- Right Front Wheel -->
  <link name="Right_FR_Wheel">
    <inertial>
      <origin xyz="0 0 0" rpy="0 0 0"/>
      <mass value="0.5"/>
      <inertia ixx="0.004" ixy="0.0" ixz="0.0"
               iyy="0.004" iyz="0.0" izz="0.002"/>
    </inertial>
    <visual>
      <origin xyz="0 0 0" rpy="0 0 0"/>
      <geometry>
        <mesh filename="/home/athira/Documents/Small_ROS/src/meshes/Right_FR_Wheel.STL"/>
      </geometry>
      <material name="blue">
        <color rgba="0.792 0.820 0.933 1"/>
      </material>
    </visual>
    <collision>
      <origin xyz="0 0 0" rpy="0 0 0"/>
      <geometry>
        <mesh filename="/home/athira/Documents/Small_ROS/src/meshes/Right_FR_Wheel.STL"/>
      </geometry>
    </collision>
  </link>
  
  <joint name="Right_FR_Wheel_joint" type="continuous">
    <parent link="base_link"/>
    <child link="Right_FR_Wheel"/>
    <origin xyz="0.66701 -1.1442 1.0732" rpy="-1.5708 0 3.1416"/>
    <axis xyz="0 1 0"/>
    <limit effort="5" velocity="3"/>
    <dynamics damping="0.5" friction="0.1"/>
  </joint>

  <!-- Left Back Wheel -->
  <link name="Left_BK_Wheel">
    <inertial>
      <origin xyz="0 0 0" rpy="0 0 0"/>
      <mass value="0.5"/>
      <inertia ixx="0.004" ixy="0.0" ixz="0.0"
               iyy="0.004" iyz="0.0" izz="0.002"/>
    </inertial>
    <visual>
      <origin xyz="0 0 0" rpy="0 0 0"/>
      <geometry>
        <mesh filename="/home/athira/Documents/Small_ROS/src/meshes/Left_BK_Wheel.STL"/>
      </geometry>
      <material name="blue">
        <color rgba="0.792 0.820 0.933 1"/>
      </material>
    </visual>
    <collision>
      <origin xyz="0 0 0" rpy="0 0 0"/>
      <geometry>
        <mesh filename="/home/athira/Documents/Small_ROS/src/meshes/Left_BK_Wheel.STL"/>
      </geometry>
    </collision>
  </link>
  
  <joint name="Left_BK_Wheel_joint" type="continuous">
    <parent link="base_link"/>
    <child link="Left_BK_Wheel"/>
    <origin xyz="-0.2 0.15 -0.1" rpy="0 0 0"/>
    <axis xyz="0 1 0"/>
    <limit effort="5" velocity="3"/>
    <dynamics damping="0.5" friction="0.1"/>
  </joint>

  <!-- Right Back Wheel -->
  <link name="Right_BK_Wheel">
    <inertial>
      <origin xyz="0 0 0" rpy="0 0 0"/>
      <mass value="0.5"/>
      <inertia ixx="0.004" ixy="0.0" ixz="0.0"
               iyy="0.004" iyz="0.0" izz="0.002"/>
    </inertial>
    <visual>
      <origin xyz="0 0 0" rpy="0 0 0"/>
      <geometry>
        <mesh filename="/home/athira/Documents/Small_ROS/src/meshes/Right_BK_Wheel.STL"/>
      </geometry>
      <material name="blue">
        <color rgba="0.792 0.820 0.933 1"/>
      </material>
    </visual>
    <collision>
      <origin xyz="0 0 0" rpy="0 0 0"/>
      <geometry>
        <mesh filename="/home/athira/Documents/Small_ROS/src/meshes/Right_BK_Wheel.STL"/>
      </geometry>
    </collision>
  </link>
  
  <joint name="Right_BK_Wheel_joint" type="continuous">
    <parent link="base_link"/>
    <child link="Right_BK_Wheel"/>
    <origin xyz="-0.2 0.15 0.1" rpy="0 0 0"/>
    <axis xyz="0 1 0"/>
    <limit effort="5" velocity="3"/>
    <dynamics damping="0.5" friction="0.1"/>
  </joint>

  <!-- Gazebo-specific properties -->
  <gazebo reference="base_link">
    <material>Gazebo/Blue</material>
    <mu1>0.2</mu1>
    <mu2>0.2</mu2>
    <kp>10000.0</kp>
    <kd>1.0</kd>
  </gazebo>

  <gazebo reference="Left_FR_Wheel">
    <material>Gazebo/Black</material>
    <mu1>0.8</mu1>
    <mu2>0.8</mu2>
    <kp>10000.0</kp>
    <kd>1.0</kd>
  </gazebo>

  <gazebo reference="Right_FR_Wheel">
    <material>Gazebo/Black</material>
    <mu1>0.8</mu1>
    <mu2>0.8</mu2>
    <kp>10000.0</kp>
    <kd>1.0</kd>
  </gazebo>

  <gazebo reference="Left_BK_Wheel">
    <material>Gazebo/Black</material>
    <mu1>0.8</mu1>
    <mu2>0.8</mu2>
    <kp>10000.0</kp>
    <kd>1.0</kd>
  </gazebo>

  <gazebo reference="Right_BK_Wheel">
    <material>Gazebo/Black</material>
    <mu1>0.8</mu1>
    <mu2>0.8</mu2>
    <kp>10000.0</kp>
    <kd>1.0</kd>
  </gazebo>

  <!-- ros2_control -->
  <!-- <ros2_control name="DiffBotSystem" type="system">
    <hardware>
      <plugin>diffbot_hardware/DiffBotSystemHardware</plugin>
      <param name="device">/dev/ttyUSB0</param>
      <param name="baud_rate">115200</param>
    </hardware>
    <joint name="Left_FR_Wheel_joint">
      <command_interface name="velocity"/>
      <state_interface name="position"/>
      <state_interface name="velocity"/>
    </joint>
    <joint name="Right_FR_Wheel_joint">
      <command_interface name="velocity"/>
      <state_interface name="position"/>
      <state_interface name="velocity"/>
    </joint>
    <joint name="Left_BK_Wheel_joint">
      <command_interface name="velocity"/>
      <state_interface name="position"/>
      <state_interface name="velocity"/>
    </joint>
    <joint name="Right_BK_Wheel_joint">
      <command_interface name="velocity"/>
      <state_interface name="position"/>
      <state_interface name="velocity"/>
    </joint>
  </ros2_control> -->

</robot>